Workbook

Sheet банк ва ҳудуд кесимида
AB1: 4
C2: Ҳудуд ва банк номи | D2: Банк бўлинмаси номи | E2: 2025 йил 1 май ҳолатига | R2: 2026 йил 1 январъ ҳолатига | AD2: 2026 йил 1-май ҳолатига
E3: Импорт шартнома сони | F3: Экспорт шартнома сони | G3: Импорт учун тўлов | H3: Экспорт тушуми | I3: Вилоят ҳудудида рўйҳатдан ўтган корхоналар | M3: Вилоят ҳудудида рўйҳатдан ўтган ва бошқа худуд банкларида фаолият юритаётган корхоналар | Q3: Дебиторка 2025 йил 1 май ҳолатига | R3: Импорт шартнома сони | S3: Экспорт шартнома сони | T3: Импорт учун тўлов | U3: Экспорт тушуми | V3: Вилоят ҳудудида рўйҳатдан ўтган корхоналар | Z3: Вилоят ҳудудида рўйҳатдан ўтган ва бошқа худуд банкларида фаолият юритаётган корхоналар | AD3: Импорт шартнома сони | AE3: Экспорт шартнома сони | AF3: Импорт учун тўлов | AG3: Экспорт тушуми | AH3: Вилоят ҳудудида рўйҳатдан ўтган корхоналар | AL3: Вилоят ҳудудида рўйҳатдан ўтган ва бошқа худуд банкларида фаолият юритаётган корхоналар | AP3: Дебиторка 2026 йил 1 май ҳолатига | AQ3: Белгиланган тоифа | AR3: 2026 йилда ҳудуддаги улуши (фоизда) | AS3: 2026 йил 1 май ҳолатига олинган банк даромади (минг сўмда) | AT3: 2025 йил 1 май ҳолатга олинган банк даромади (минг сўмда) | AU3: Аккредитив хисобрақам очиш | AV3: Факторинг хизмати мавжудлиги | AW3: Мавжуд ходимлар | AX3: Қамрови
I4: Экспорт тушуми | K4: Импорт тўлови | M4: Экспорт тушуми | O4: Импорт тўлови | V4: Экспорт тушуми | X4: Импорт тўлови | Z4: Экспорт тушуми | AB4: Импорт тўлови | AH4: Экспорт тушуми | AJ4: Импорт тўлови | AL4: Экспорт тушуми | AN4: Импорт тўлови
B5: 1 | I5: Шартнома сони | J5: Суммаси | K5: Шартнома сони | L5: Суммаси | M5: Шартнома сони | N5: Суммаси | O5: Шартнома сони | P5: Суммаси | V5: Шартнома сони | W5: Суммаси | X5: Шартнома сони | Y5: Суммаси | Z5: Шартнома сони | AA5: Суммаси | AB5: Шартнома сони | AC5: Суммаси | AH5: Шартнома сони | AI5: Суммаси | AJ5: Шартнома сони | AK5: Суммаси | AL5: Шартнома сони | AM5: Суммаси | AN5: Шартнома сони | AO5: Суммаси
E6: =+E7+E13+E16+E20+E23+E28+E35+E39+E41+E50+E53+E58+E61+E63+E67+E70+E73+E77+E83+E86+E89+E94+E246 -> 15744.667 | F6: =+F7+F13+F16+F20+F23+F28+F35+F39+F41+F50+F53+F58+F61+F63+F67+F70+F73+F77+F83+F86+F89+F94+F246 -> 7784.7778 | G6: =+G7+G13+G16+G20+G23+G28+G35+G39+G41+G50+G53+G58+G61+G63+G67+G70+G73+G77+G83+G86+G89+G94+G246 -> 1.3515402e+09 | H6: =+H7+H13+H16+H20+H23+H28+H35+H39+H41+H50+H53+H58+H61+H63+H67+H70+H73+H77+H83+H86+H89+H94+H246 -> 5.5406516e+08 | I6: =+I7+I13+I16+I20+I23+I28+I35+I39+I41+I50+I53+I58+I61+I63+I67+I70+I73+I77+I83+I86+I89+I94+I246 -> 1844.7778 | J6: =+J7+J13+J16+J20+J23+J28+J35+J39+J41+J50+J53+J58+J61+J63+J67+J70+J73+J77+J83+J86+J89+J94+J246 -> 1.6203574e+08 | K6: =+K7+K13+K16+K20+K23+K28+K35+K39+K41+K50+K53+K58+K61+K63+K67+K70+K73+K77+K83+K86+K89+K94+K246 -> 2113.6667 | L6: =+L7+L13+L16+L20+L23+L28+L35+L39+L41+L50+L53+L58+L61+L63+L67+L70+L73+L77+L83+L86+L89+L94+L246 -> 2.8592702e+08 | ... U6: =+U7+U13+U16+U20+U23+U28+U35+U39+U41+U50+U53+U58+U61+U63+U67+U70+U73+U77+U83+U86+U89+U94+U246 -> 6.5830006e+08 | V6: =+S6 -> 8495.2222 | W6: =+W7+W13+W16+W20+W23+W28+W35+W39+W41+W50+W53+W58+W61+W63+W67+W70+W73+W77+W83+W86+W89+W94+W246 -> 6.5830006e+08 | X6: =+X7+X13+X16+X20+X23+X28+X35+X39+X41+X50+X53+X58+X61+X63+X67+X70+X73+X77+X83+X86+X89+X94+X246 -> 18523 | Y6: =+Y7+Y13+Y16+Y20+Y23+Y28+Y35+Y39+Y41+Y50+Y53+Y58+Y61+Y63+Y67+Y70+Y73+Y77+Y83+Y86+Y89+Y94+Y246 -> 1.9189952e+09 | Z6: =+Z7+Z13+Z16+Z20+Z23+Z28+Z35+Z39+Z41+Z50+Z53+Z58+Z61+Z63+Z67+Z70+Z73+Z77+Z83+Z86+Z89+Z94+Z246 -> 11697.778 | AA6: =+AA7+AA13+AA16+AA20+AA23+AA28+AA35+AA39+AA41+AA50+AA53+AA58+AA61+AA63+AA67+AA70+AA73+AA77+AA83+AA86+AA89+AA94+AA246 -> 5.7970111e+08 | AB6: =+AB7+AB13+AB16+AB20+AB23+AB28+AB35+AB39+AB41+AB50+AB53+AB58+AB61+AB63+AB67+AB70+AB73+AB77+AB83+AB86+AB89+AB94+AB246 -> 20920 | AC6: =+AC7+AC13+AC16+AC20+AC23+AC28+AC35+AC39+AC41+AC50+AC53+AC58+AC61+AC63+AC67+AC70+AC73+AC77+AC83+AC86+AC89+AC94+AC246 -> 1.490662e+09 | AD6: =+AD7+AD13+AD16+AD20+AD23+AD28+AD35+AD39+AD41+AD50+AD53+AD58+AD61+AD63+AD67+AD70+AD73+AD77+AD83+AD86+AD89+AD94+AD246 -> 15868.889 | ... AP6: =+AP7+AP13+AP16+AP20+AP23+AP28+AP35+AP39+AP41+AP50+AP53+AP58+AP61+AP63+AP67+AP70+AP73+AP77+AP83+AP86+AP89+AP94+AP246 -> 787692.46 | AR6: =+AR7+AR13+AR16+AR20+AR23+AR28+AR35+AR39+AR41+AR50+AR53+AR58+AR61+AR63+AR67+AR70+AR73+AR77+AR83+AR86+AR89+AR94+AR246 -> 5 | AS6: =+AS7+AS13+AS16+AS20+AS23+AS28+AS35+AS39+AS41+AS50+AS53+AS58+AS61+AS63+AS67+AS70+AS73+AS77+AS83+AS86+AS89+AS94+AS246 -> 8769391.9 | AT6: =+AT7+AT13+AT16+AT20+AT23+AT28+AT35+AT39+AT41+AT50+AT53+AT58+AT61+AT63+AT67+AT70+AT73+AT77+AT83+AT86+AT89+AT94+AT246 -> 2682628.8 | AU6: =+AU7+AU13+AU16+AU20+AU23+AU28+AU35+AU39+AU41+AU50+AU53+AU58+AU61+AU63+AU67+AU70+AU73+AU77+AU83+AU86+AU89+AU94+AU246 -> 0 | AV6: =+AV7+AV13+AV16+AV20+AV23+AV28+AV35+AV39+AV41+AV50+AV53+AV58+AV61+AV63+AV67+AV70+AV73+AV77+AV83+AV86+AV89+AV94+AV246 -> 0 | AW6: =+AW7+AW13+AW16+AW20+AW23+AW28+AW35+AW39+AW41+AW50+AW53+AW58+AW61+AW63+AW67+AW70+AW73+AW77+AW83+AW86+AW89+AW94+AW246 -> 122 | AX6: =+AX7+AX13+AX16+AX20+AX23+AX28+AX35+AX39+AX41+AX50+AX53+AX58+AX61+AX63+AX67+AX70+AX73+AX77+AX83+AX86+AX89+AX94+AX246 -> 6.490674e+08
A7: Ангрен шаҳар | C7: Ангрен шаҳар | E7: =+SUM(E8:E12) -> 215 | F7: =+SUM(F8:F12) -> 604 | G7: =+SUM(G8:G12) -> 12397252 | H7: =+SUM(H8:H12) -> 7569987.1 | I7: =+SUM(I8:I12) -> 441 | J7: =+SUM(J8:J12) -> 5393874.5 | K7: =+SUM(K8:K12) -> 156 | L7: =+SUM(L8:L12) -> 9458328.4 | ... Q7: =+SUM(Q8:Q12) -> 557.16441 | R7: 239 | S7: =+SUM(S8:S12) -> 513 | T7: 11614722 | U7: =+SUM(U8:U12) -> 11377138 | V7: =+S7 -> 513 | W7: =+U7 -> 11377138 | X7: =+R7 -> 239 | Y7: =+T7 -> 11614722 | Z7: =((+SUM(Z8:Z12))/3)*4 -> 0 | AA7: =((+SUM(AA8:AA12))/3)*4 -> 0 | AB7: 0 | AC7: 0 | AD7: =+SUM(AD8:AD12) -> 310 | AE7: =+SUM(AE8:AE12) -> 676 | AF7: =+SUM(AF8:AF12) -> 11386291 | AG7: =+SUM(AG8:AG12) -> 12623819 | AH7: =+AE7 -> 676 | AI7: =+AG7 -> 12623819 | AJ7: =+AD7 -> 310 | AK7: =+AF7 -> 11386291 | AL7: =((((+SUM(AL8:AL12))/3)*4)/3)*4 -> 0 | AM7: =((((+SUM(AM8:AM12))/3)*4)/3)*4 -> 0 | AN7: =((((+SUM(AN8:AN12))/3)*4)/3)*4 -> 0 | AO7: =((((+SUM(AO8:AO12))/3)*4)/3)*4 -> 0 | AP7: =+SUM(AP8:AP12) -> 2430.2686 | AQ7: Ўртача | AR7: =+SUM(AR8:AR12) -> 1 | AS7: =+SUM(AS8:AS12) -> 440834.88 | AT7: =+SUM(AT8:AT12) -> 252011.18 | AW7: =+SUM(AW8:AW12) -> 9 | AX7: =+AI7+AK7+AM7+AO7 -> 24010110 | AY7: =+AX7/$AX$6 -> 0.036991705
B8: 461 | C8: Ипотека банк | D8: Ипотека банк Ангрен филиали | E8: 36 | F8: 68 | G8: 895568.28 | H8: 1157013.1 | I8: 49 | J8: 788896.95 | K8: 33 | L8: 859902.38 | M8: 0 | N8: 0 | O8: 0 | P8: 0 | Q8: 88.69364 | R8: 37 | S8: =+VLOOKUP(B8,[1]Лист2!$A$4:$B$188,2,0) -> 44 | T8: 436727.73 | U8: =+VLOOKUP(B8,[1]Лист2!$A$4:$C$188,3,0) -> 392003.3 | V8: =+S8 -> 44 | W8: =+U8 -> 392003.3 | X8: =+R8 -> 37 | Y8: =+T8 -> 436727.73 | Z8: 0 | AA8: 0 | AB8: 0 | AC8: 0 | AD8: 30 | AE8: 106 | AF8: 518681.83 | AG8: 1014168.6 | AH8: =+AE8 -> 106 | AI8: =+AG8 -> 1014168.6 | AJ8: =+AD8 -> 30 | AK8: =+AF8 -> 518681.83 | AL8: 0 | AM8: 0 | AN8: 0 | AO8: 0 | AP8: 248.98248 | AQ8: Ўртача | AR8: =+AX8/$AX$7 -> 0.063841876 | AS8: 0 | AT8: 141802.46 | AU8: Бор | AV8: Бор | AW8: 2 | AX8: =+AI8+AK8 -> 1532850.5
B9: 11254 | C9: Миллийбанк | D9: Миллийбанк Ангрен БХМ | E9: 24 | F9: 7 | G9: 4566399.9 | H9: 275309.24 | I9: 3 | J9: 121969.72 | K9: 17 | L9: 3772518.2 | M9: 0 | N9: 0 | O9: 0 | P9: 0 | Q9: 0 | R9: 26 | S9: =+VLOOKUP(B9,[1]Лист2!$A$4:$B$188,2,0) -> 31 | T9: 2366204.9 | U9: =+VLOOKUP(B9,[1]Лист2!$A$4:$C$188,3,0) -> 626407.15 | V9: =+S9 -> 31 | W9: =+U9 -> 626407.15 | X9: =+R9 -> 26 | Y9: =+T9 -> 2366204.9 | Z9: 0 | AA9: 0 | AB9: 0 | AC9: 0 | AD9: 34 | AE9: 34 | AF9: 1138513.9 | AG9: 921146.93 | AH9: =+AE9 -> 34 | AI9: =+AG9 -> 921146.93 | AJ9: =+AD9 -> 34 | AK9: =+AF9 -> 1138513.9 | AL9: 0 | AM9: 0 | AN9: 0 | AO9: 0 | AP9: 48.68434 | AQ9: Барқарор | AR9: =+AX9/$AX$7 -> 0.085783067 | AS9: 15117.543 | AT9: 3779.3859 | AU9: Бор | AV9: Бор | AW9: 2 | AX9: =+AI9+AK9 -> 2059660.9
B10: 11199 | C10: Ўзсаноатқурилишбанк | D10: Ўзсаноатқурилишбанк Ангрен БХМ | E10: 11 | F10: 31 | G10: 311060 | H10: 702627.35 | I10: 26 | J10: 667205.59 | K10: 8 | L10: 265220 | M10: 0 | N10: 0 | O10: 0 | P10: 0 | Q10: 259.64941 | R10: 9 | S10: =+VLOOKUP(B10,[1]Лист2!$A$4:$B$188,2,0) -> 28 | T10: 240800 | U10: =+VLOOKUP(B10,[1]Лист2!$A$4:$C$188,3,0) -> 460973.8 | V10: =+S10 -> 28 | W10: =+U10 -> 460973.8 | X10: =+R10 -> 9 | Y10: =+T10 -> 240800 | Z10: 0 | AA10: 0 | AB10: 0 | AC10: 0 | AD10: 18 | AE10: 40 | AF10: 255476.4 | AG10: 479915.01 | AH10: =+AE10 -> 40 | AI10: =+AG10 -> 479915.01 | AJ10: =+AD10 -> 18 | AK10: =+AF10 -> 255476.4 | AL10: 0 | AM10: 0 | AN10: 0 | AO10: 0 | AP10: 285.95141 | AQ10: Самарадорлиги паст | AR10: =+AX10/$AX$7 -> 0.030628407 | AS10: 8333.3333 | AT10: 2083.3333 | AU10: Йуқ | AV10: Йуқ | AW10: 2 | AX10: =+AI10+AK10 -> 735391.41
B11: 11581 | C11: Халқ банк | D11: Халқ банк Ангрен БХМ | E11: 0 | F11: 1 | G11: 0 | H11: 20000 | I11: 1 | J11: 20000 | K11: 0 | L11: 0 | M11: 0 | N11: 0 | O11: 0 | P11: 0 | Q11: 0 | V11: =+S11 -> 0 | W11: =+U11 -> 0 | X11: =+R11 -> 0 | Y11: =+T11 -> 0 | Z11: =((+S11)/3)*4 -> 0 | AA11: =((+U11)/3)*4 -> 0 | AB11: 0 | AC11: 0 | AD11: 0 | AE11: 0 | AF11: 0 | AG11: 0 | AH11: =+AE11 -> 0 | AI11: =+AG11 -> 0 | AJ11: =+AD11 -> 0 | AK11: =+AF11 -> 0 | AL11: 0 | AM11: 0 | AN11: 0 | AO11: 0 | AP11: 0 | AQ11: Самарадорлиги паст | AR11: =+AX11/$AX$7 -> 0 | AS11: 0 | AT11: 0 | AU11: Бор | AV11: Бор | AW11: 2 | AX11: =+AI11+AK11 -> 0
B12: 11446 | C12: Ҳамкорбанк | D12: Ҳамкорбанк Ангрен филиали | E12: 144 | F12: 497 | G12: 6624224 | H12: 5415037.3 | I12: 362 | J12: 3795802.2 | K12: 98 | L12: 4560687.8 | M12: 0 | N12: 0 | O12: 0 | P12: 0 | Q12: 208.82136 | R12: 167 | S12: =+VLOOKUP(B12,[1]Лист2!$A$4:$B$188,2,0) -> 410 | T12: 8570989.6 | U12: =+VLOOKUP(B12,[1]Лист2!$A$4:$C$188,3,0) -> 9897753.4 | V12: =+S12 -> 410 | W12: =+U12 -> 9897753.4 | X12: =+R12 -> 167 | Y12: =+T12 -> 8570989.6 | Z12: 0 | AA12: 0 | AB12: 0 | AC12: 0 | AD12: 228 | AE12: 496 | AF12: 9473619 | AG12: 10208588 | AH12: =+AE12 -> 496 | AI12: =+AG12 -> 10208588 | AJ12: =+AD12 -> 228 | AK12: =+AF12 -> 9473619 | AL12: 0 | AM12: 0 | AN12: 0 | AO12: 0 | AP12: 1846.6504 | AQ12: Самарадор | AR12: =+AX12/$AX$7 -> 0.81974665 | AS12: 417384 | AT12: 104346 | AU12: Бор | AV12: Бор | AW12: 1 | AX12: =+AI12+AK12 -> 19682207
A13: Бекобод тумани | C13: Бекобод тумани | E13: =+SUM(E14:E15) -> 5 | F13: =+SUM(F14:F15) -> 7 | G13: =+SUM(G14:G15) -> 93135 | H13: =+SUM(H14:H15) -> 166500 | I13: =+SUM(I14:I15) -> 5 | J13: =+SUM(J14:J15) -> 133500 | K13: =+SUM(K14:K15) -> 3 | L13: =+SUM(L14:L15) -> 83036 | ... AP13: =+SUM(AP14:AP15) -> 11.4975 | AQ13: Самарадорлиги паст | AS13: =+SUM(AS14:AS15) -> 0 | AT13: =+SUM(AT14:AT15) -> 0 | AW13: =+SUM(AW14:AW15) -> 4 | AX13: =+AI13+AK13+AM13+AO13 -> 354250 | AY13: =+AX13/$AX$6 -> 0.00054578307
B14: 468 | C14: Агробанк | D14: Агробанк Бекобод филиали | E14: 5 | F14: 7 | G14: 93135 | H14: 166500 | I14: 5 | J14: 133500 | K14: 3 | L14: 83036 | M14: 0 | N14: 0 | O14: 0 | P14: 0 | Q14: 0 | R14: 3 | T14: 38275 | V14: =+S14 -> 0 | W14: =+U14 -> 0 | X14: =+R14 -> 3 | Y14: =+T14 -> 38275 | Z14: =((+S14)/3)*4 -> 0 | AA14: =((+U14)/3)*4 -> 0 | AB14: 0 | AC14: 0 | AD14: 2 | AE14: 2 | AF14: 38250 | AG14: 60000 | AH14: =+AE14 -> 2 | AI14: =+AG14 -> 60000 | AJ14: =+AD14 -> 2 | AK14: =+AF14 -> 38250 | AL14: 0 | AM14: 0 | AN14: 0 | AO14: 0 | AP14: 7.035 | AQ14: Барқарор | AR14: =+AX14/$AX$13 -> 0.27734651 | AS14: 0 | AT14: 0 | AU14: Бор | AV14: Бор | AW14: 2 | AX14: =+AI14+AK14 -> 98250
B15: 11634 | C15: Халқ банк | D15: Халқ банк Бекобод БХМ | E15: 0 | F15: 0 | G15: 0 | H15: 0 | I15: 0 | J15: 0 | K15: 0 | L15: 0 | M15: 0 | N15: 0 | O15: 0 | P15: 0 | Q15: 4.4625 | V15: =+S15 -> 0 | W15: =+U15 -> 0 | X15: =+R15 -> 0 | Y15: =+T15 -> 0 | Z15: =((+S15)/3)*4 -> 0 | AA15: =((+U15)/3)*4 -> 0 | AB15: 0 | AC15: 0 | AD15: 2 | AE15: 0 | AF15: 256000 | AG15: 0 | AH15: =+AE15 -> 0 | AI15: =+AG15 -> 0 | AJ15: =+AD15 -> 2 | AK15: =+AF15 -> 256000 | AL15: 0 | AM15: 0 | AN15: 0 | AO15: 0 | AP15: 4.4625 | AQ15: Самарадор | AR15: =+AX15/$AX$13 -> 0.72265349 | AS15: 0 | AT15: 0 | AU15: Бор | AV15: Бор | AW15: 2 | AX15: =+AI15+AK15 -> 256000
A16: Бекобод шаҳар | C16: Бекобод шаҳар | E16: =+SUM(E17:E19) -> 173 | F16: =+SUM(F17:F19) -> 164 | G16: =+SUM(G17:G19) -> 44957952 | H16: =+SUM(H17:H19) -> 7024960.4 | I16: =+SUM(I17:I19) -> 111 | J16: =+SUM(J17:J19) -> 4263442 | K16: =+SUM(K17:K19) -> 125 | L16: =+SUM(L17:L19) -> 42582191 | ... AP16: =+SUM(AP17:AP19) -> 6340.3611 | AQ16: Барқарор | AS16: =+SUM(AS17:AS19) -> 347622.69 | AT16: =+SUM(AT17:AT19) -> 220626.34 | AU16: =+SUM(AU17:AU19) -> 0 | AV16: =+SUM(AV17:AV19) -> 0 | AW16: =+SUM(AW17:AW19) -> 6 | AX16: =+AI16+AK16+AM16+AO16 -> 46647232 | AY16: =+AX16/$AX$6 -> 0.071868086
B17: 489 | C17: Ипотека банк | D17: Ипотека банк Бекобод филиали | E17: 43 | F17: 76 | G17: 3058598.3 | H17: 4475589.3 | I17: 53 | J17: 2950376.4 | K17: 37 | L17: 2873448.3 | M17: 0 | N17: 0 | O17: 0 | P17: 0 | Q17: 206.62577 | R17: 27 | S17: =+VLOOKUP(B17,[1]Лист2!$A$4:$B$188,2,0) -> 25 | T17: 1670879.6 | U17: =+VLOOKUP(B17,[1]Лист2!$A$4:$C$188,3,0) -> 1232167.7 | V17: =+S17 -> 25 | W17: =+U17 -> 1232167.7 | X17: =+R17 -> 27 | Y17: =+T17 -> 1670879.6 | Z17: 0 | AA17: 0 | AB17: 0 | AC17: 0 | AD17: 29 | AE17: 31 | AF17: 2832942.3 | AG17: 925115.22 | AH17: =+AE17 -> 31 | AI17: =+AG17 -> 925115.22 | AJ17: =+AD17 -> 29 | AK17: =+AF17 -> 2832942.3 | AL17: 0 | AM17: 0 | AN17: 0 | AO17: 0 | AP17: 2307.3477 | AQ17: Ўртача | AR17: =+AX17/$AX$16 -> 0.080563356 | AS17: 102562.67 | AT17: 159361.33 | AU17: Бор | AV17: Бор | AW17: 2 | AX17: =+AI17+AK17 -> 3758057.5
B18: 11256 | C18: Миллийбанк | D18: Миллийбанк Бекобод БХМ | E18: 112 | F18: 58 | G18: 41641915 | H18: 2442977.9 | I18: 31 | J18: 1225942.2 | K18: 77 | L18: 39575775 | M18: 0 | N18: 0 | O18: 0 | P18: 0 | Q18: 854.08928 | R18: 139 | S18: =+VLOOKUP(B18,[1]Лист2!$A$4:$B$188,2,0) -> 61 | T18: 23003054 | U18: =+VLOOKUP(B18,[1]Лист2!$A$4:$C$188,3,0) -> 3285989.1 | V18: =+S18 -> 61 | W18: =+U18 -> 3285989.1 | X18: =+R18 -> 139 | Y18: =+T18 -> 23003054 | Z18: 0 | AA18: 0 | AB18: 0 | AC18: 0 | AD18: 130 | AE18: 81 | AF18: 37918546 | AG18: 4498509.9 | AH18: =+AE18 -> 81 | AI18: =+AG18 -> 4498509.9 | AJ18: =+AD18 -> 130 | AK18: =+AF18 -> 37918546 | AL18: 0 | AM18: 0 | AN18: 0 | AO18: 0 | AP18: 3116.4955 | AQ18: Самарадор | AR18: =+AX18/$AX$16 -> 0.9093156 | AS18: 235657.36 | AT18: 58914.339 | AU18: Бор | AV18: Бор | AW18: 2 | AX18: =+AI18+AK18 -> 42417055
B19: 11203 | C19: Ўзсаноатқурилишбанк | D19: Ўзсаноатқурилишбанк Бекобод БХМ | E19: 18 | F19: 30 | G19: 257438.07 | H19: 106393.3 | I19: 27 | J19: 87123.3 | K19: 11 | L19: 132967.09 | M19: 0 | N19: 0 | O19: 0 | P19: 0 | Q19: 1041.2382 | R19: 8 | S19: =+VLOOKUP(B19,[1]Лист2!$A$4:$B$188,2,0) -> 16 | T19: 180733 | U19: =+VLOOKUP(B19,[1]Лист2!$A$4:$C$188,3,0) -> 61285.95 | V19: =+S19 -> 16 | W19: =+U19 -> 61285.95 | X19: =+R19 -> 8 | Y19: =+T19 -> 180733 | Z19: 0 | AA19: 0 | AB19: 0 | AC19: 0 | AD19: 21 | AE19: 22 | AF19: 385535.14 | AG19: 86583.61 | AH19: =+AE19 -> 22 | AI19: =+AG19 -> 86583.61 | AJ19: =+AD19 -> 21 | AK19: =+AF19 -> 385535.14 | AL19: 0 | AM19: 0 | AN19: 0 | AO19: 0 | AP19: 916.51787 | AQ19: Самарадорлиги паст | AR19: =+AX19/$AX$16 -> 0.010121045 | AS19: 9402.6667 | AT19: 2350.6667 | AU19: Бор | AV19: Бор | AW19: 2 | AX19: =+AI19+AK19 -> 472118.75
A20: Бўка тумани | C20: Бўка тумани | E20: =+E21+E22 -> 4 | F20: =+F21+F22 -> 7 | G20: =+G21+G22 -> 105870 | H20: =+H21+H22 -> 190051.13 | I20: =+I21+I22 -> 6 | J20: =+J21+J22 -> 160603.13 | K20: =+K21+K22 -> 2 | L20: =+L21+L22 -> 59970 | ... AP20: =+AP21+AP22 -> 6.10188 | AQ20: Самарадорлиги паст | AR20: =+AR21+AR22 -> 1 | AS20: =+AS21+AS22 -> 7066.6667 | AT20: =+AT21+AT22 -> 0 | AW20: =+AW21+AW22 -> 4 | AX20: =+AI20+AK20+AM20+AO20 -> 543379.24 | AY20: =+AX20/$AX$6 -> 0.0008371692
B21: 463 | C21: Агробанк | D21: Агробанк Бўка филиали | E21: 0 | F21: 0 | G21: 0 | H21: 0 | I21: 0 | J21: 0 | K21: 0 | L21: 0 | M21: 0 | N21: 0 | O21: 0 | P21: 0 | Q21: 0 | V21: =+S21 -> 0 | W21: =+U21 -> 0 | X21: =+R21 -> 0 | Y21: =+T21 -> 0 | Z21: =((+S21)/3)*4 -> 0 | AA21: =((+U21)/3)*4 -> 0 | AB21: 0 | AC21: 0 | AD21: 5 | AE21: 0 | AF21: 52474.94 | AG21: 0 | AH21: =+AE21 -> 0 | AI21: =+AG21 -> 0 | AJ21: =+AD21 -> 5 | AK21: =+AF21 -> 52474.94 | AL21: 0 | AM21: 0 | AN21: 0 | AO21: 0 | AP21: 0 | AQ21: Ўртача | AR21: =+AX21/$AX$20 -> 0.096571485 | AS21: 0 | AT21: 0 | AU21: Бор | AV21: Бор | AW21: 2 | AX21: =+AI21+AK21 -> 52474.94
B22: 10792 | C22: Ўзсаноатқурилишбанк | D22: Ўзсаноатқурилишбанк Бўка БХМ | E22: 4 | F22: 7 | G22: 105870 | H22: 190051.13 | I22: 6 | J22: 160603.13 | K22: 2 | L22: 59970 | M22: 0 | N22: 0 | O22: 0 | P22: 0 | Q22: 21.00188 | R22: 2 | S22: =+VLOOKUP(B22,[1]Лист2!$A$4:$B$188,2,0) -> 7 | T22: 24727.95 | U22: =+VLOOKUP(B22,[1]Лист2!$A$4:$C$188,3,0) -> 431626.06 | V22: =+S22 -> 7 | W22: =+U22 -> 431626.06 | X22: =+R22 -> 2 | Y22: =+T22 -> 24727.95 | Z22: 0 | AA22: 0 | AB22: 0 | AC22: 0 | AD22: 1 | AE22: 11 | AF22: 96120 | AG22: 394784.3 | AH22: =+AE22 -> 11 | AI22: =+AG22 -> 394784.3 | AJ22: =+AD22 -> 1 | AK22: =+AF22 -> 96120 | AL22: 0 | AM22: 0 | AN22: 0 | AO22: 0 | AP22: 6.10188 | AQ22: Самарадор | AR22: =+AX22/$AX$20 -> 0.90342852 | AS22: 7066.6667 | AT22: 0 | AU22: Йуқ | AV22: Йуқ | AW22: 2 | AX22: =+AI22+AK22 -> 490904.3
A23: Бўстонлиқ тумани | C23: Бўстонлиқ тумани | E23: =+SUM(E24:E27) -> 24 | F23: =+SUM(F24:F27) -> 1 | G23: =+SUM(G24:G27) -> 1176373.3 | H23: =+SUM(H24:H27) -> 8000 | I23: =+SUM(I24:I27) -> 1 | J23: =+SUM(J24:J27) -> 8000 | K23: =+SUM(K24:K27) -> 7 | L23: =+SUM(L24:L27) -> 144831.92 | ... AP23: =+SUM(AP24:AP27) -> 266.42876 | AQ23: Самарадорлиги паст | AR23: =+SUM(AR24:AR27) -> 1 | AS23: =+SUM(AS24:AS27) -> 145900 | AT23: =+SUM(AT24:AT27) -> 36475 | AW23: =+SUM(AW24:AW27) -> 8 | AX23: =+AI23+AK23+AM23+AO23 -> 452897.5 | AY23: =+AX23/$AX$6 -> 0.00069776652
B24: 12129 | C24: Бизнесни ривожлантириш банки | D24: Бизнесни ривожлантириш банки Бўстонлиқ БХМ | E24: 8 | F24: 1 | G24: 145131.73 | H24: 8000 | I24: 1 | J24: 8000 | K24: 7 | L24: 144831.92 | M24: 0 | N24: 0 | O24: 0 | P24: 0 | Q24: 30.844 | S24: =+VLOOKUP(B24,[1]Лист2!$A$4:$B$188,2,0) -> 1 | U24: =+VLOOKUP(B24,[1]Лист2!$A$4:$C$188,3,0) -> 2000 | V24: =+S24 -> 1 | W24: =+U24 -> 2000 | X24: =+R24 -> 0 | Y24: =+T24 -> 0 | Z24: 0 | AA24: 0 | AB24: 0 | AC24: 0 | AD24: 0 | AE24: 0 | AF24: 0 | AG24: 0 | AH24: =+AE24 -> 0 | AI24: =+AG24 -> 0 | AJ24: =+AD24 -> 0 | AK24: =+AF24 -> 0 | AL24: 0 | AM24: 0 | AN24: 0 | AO24: 0 | AP24: 66.25898 | AQ24: Самарадорлиги паст | AR24: =+AX24/$AX$23 -> 0 | AS24: 73354.667 | AT24: 18338.667 | AU24: Йуқ | AV24: Йуқ | AW24: 2 | AX24: =+AI24+AK24 -> 0
B25: 12090 | C25: Гарант банк | D25: Гарант банк Бўстонлиқ БХМ | E25: 5 | F25: 0 | G25: 305464.73 | H25: 0 | I25: 0 | J25: 0 | K25: 0 | L25: 0 | M25: 0 | N25: 0 | O25: 4 | P25: 266420.73 | Q25: 6.3304 | R25: 9 | S25: =+VLOOKUP(B25,[1]Лист2!$A$4:$B$188,2,0) -> 3 | T25: 811077.46 | U25: =+VLOOKUP(B25,[1]Лист2!$A$4:$C$188,3,0) -> 18788.98 | V25: =+S25 -> 3 | W25: =+U25 -> 18788.98 | X25: =+R25 -> 9 | Y25: =+T25 -> 811077.46 | Z25: 0 | AA25: 0 | AB25: 0 | AC25: 0 | AD25: 4 | AE25: 5 | AF25: 338044 | AG25: 66854.7 | AH25: =+AE25 -> 5 | AI25: =+AG25 -> 66854.7 | AJ25: =+AD25 -> 4 | AK25: =+AF25 -> 338044 | AL25: 0 | AM25: 0 | AN25: 0 | AO25: 0 | AP25: 32.84186 | AQ25: Самарадор | AR25: =+AX25/$AX$23 -> 0.8940184 | AS25: 62812 | AT25: 15703 | AU25: Бор | AV25: Бор | AW25: 2 | AX25: =+AI25+AK25 -> 404898.7
B26: 11413 | C26: Микрокредитбанк | D26: Микрокредитбанк Бўстонлиқ БХМ | E26: 6 | F26: 0 | G26: 370187.8 | H26: 0 | I26: 0 | J26: 0 | K26: 0 | L26: 0 | M26: 0 | N26: 0 | O26: 4 | P26: 89761.8 | Q26: 17.6382 | R26: 4 | S26: =+VLOOKUP(B26,[1]Лист2!$A$4:$B$188,2,0) -> 1 | T26: 90434 | U26: =+VLOOKUP(B26,[1]Лист2!$A$4:$C$188,3,0) -> 80000 | V26: =+S26 -> 1 | W26: =+U26 -> 80000 | X26: =+R26 -> 4 | Y26: =+T26 -> 90434 | Z26: 0 | AA26: 0 | AB26: 0 | AC26: 0 | AD26: 6 | AE26: 0 | AF26: 45638.8 | AG26: 0 | AH26: =+AE26 -> 0 | AI26: =+AG26 -> 0 | AJ26: =+AD26 -> 6 | AK26: =+AF26 -> 45638.8 | AL26: 0 | AM26: 0 | AN26: 0 | AO26: 0 | AP26: 167.32792 | AQ26: Ўртача | AR26: =+AX26/$AX$23 -> 0.1007707 | AS26: 9733.3333 | AT26: 2433.3333 | AU26: Йуқ | AV26: Йуқ | AW26: 2 | AX26: =+AI26+AK26 -> 45638.8
B27: 11183 | C27: Миллийбанк | D27: Миллийбанк Бўстонлиқ БХМ | E27: 5 | F27: 0 | G27: 355589 | H27: 0 | I27: 0 | J27: 0 | K27: 0 | L27: 0 | M27: 0 | N27: 0 | O27: 5 | P27: 355589 | Q27: 0 | V27: =+S27 -> 0 | W27: =+U27 -> 0 | X27: =+R27 -> 0 | Y27: =+T27 -> 0 | Z27: =((+S27)/3)*4 -> 0 | AA27: =((+U27)/3)*4 -> 0 | AB27: 0 | AC27: 0 | AD27: 0 | AE27: 1 | AF27: 0 | AG27: 2360 | AH27: =+AE27 -> 1 | AI27: =+AG27 -> 2360 | AJ27: =+AD27 -> 0 | AK27: =+AF27 -> 0 | AL27: 0 | AM27: 0 | AN27: 0 | AO27: 0 | AP27: 0 | AQ27: Самарадорлиги паст | AR27: =+AX27/$AX$23 -> 0.0052108921 | AS27: 0 | AT27: 0 | AU27: Бор | AV27: Бор | AW27: 2 | AX27: =+AI27+AK27 -> 2360
A28: Зангиота тумани | C28: Зангиота тумани | E28: =+SUM(E29:E34) -> 794 | F28: =+SUM(F29:F34) -> 98 | G28: =+SUM(G29:G34) -> 31944779 | H28: =+SUM(H29:H34) -> 2491610.8 | I28: =+SUM(I29:I34) -> 71 | J28: =+SUM(J29:J34) -> 2022301.4 | K28: =+SUM(K29:K34) -> 565 | L28: =+SUM(L29:L34) -> 22035466 | ... AP28: =+SUM(AP29:AP34) -> 8437.1089 | AQ28: Барқарор | AS28: =+SUM(AS29:AS34) -> 1565486 | AT28: =+SUM(AT29:AT34) -> 415689.03 | AW28: =+SUM(AW29:AW34) -> 10 | AX28: =+AI28+AK28+AM28+AO28 -> 48832635 | AY28: =+AX28/$AX$6 -> 0.075235075
B29: 12091 | C29: Гарант банк | D29: Гарант банк Зангиота БХМ | E29: 54 | F29: 1 | G29: 5363899.8 | H29: 7796.71 | I29: 0 | J29: 0 | K29: 0 | L29: 0 | M29: 0 | N29: 0 | O29: 28 | P29: 706132.7 | Q29: 87.8634 | R29: 28 | S29: =+VLOOKUP(B29,[1]Лист2!$A$4:$B$188,2,0) -> 1 | T29: 1229327.4 | U29: =+VLOOKUP(B29,[1]Лист2!$A$4:$C$188,3,0) -> 30000 | V29: =+S29 -> 1 | W29: =+U29 -> 30000 | X29: =+R29 -> 28 | Y29: =+T29 -> 1229327.4 | Z29: 0 | AA29: 0 | AB29: 0 | AC29: 0 | AD29: 75 | AE29: 1 | AF29: 8996046.8 | AG29: 12000 | AH29: =+AE29 -> 1 | AI29: =+AG29 -> 12000 | AJ29: =+AD29 -> 75 | AK29: =+AF29 -> 8996046.8 | AL29: 0 | AM29: 0 | AN29: 0 | AO29: 0 | AP29: 714.71053 | AQ29: Барқарор | AR29: =+AX29/$AX$28 -> 0.18446776 | AS29: 433102.54 | AT29: 108275.63 | AU29: Бор | AV29: Бор | AW29: 2 | AX29: =+AI29+AK29 -> 9008046.8
B30: 1080 | C30: Инфинбанк | D30: Инфинбанк Зангиота филиали | E30: 167 | F30: 55 | G30: 5144261.6 | H30: 1187320.6 | I30: 38 | J30: 903333.57 | K30: 84 | L30: 2870939.8 | M30: 0 | N30: 0 | O30: 0 | P30: 0 | Q30: 345.0125 | R30: 147 | S30: =+VLOOKUP(B30,[1]Лист2!$A$4:$B$188,2,0) -> 50 | T30: 7282514.1 | U30: =+VLOOKUP(B30,[1]Лист2!$A$4:$C$188,3,0) -> 3216836.2 | V30: =+S30 -> 50 | W30: =+U30 -> 3216836.2 | X30: =+R30 -> 147 | Y30: =+T30 -> 7282514.1 | Z30: 0 | AA30: 0 | AB30: 0 | AC30: 0 | AD30: 186 | AE30: 52 | AF30: 8171521.3 | AG30: 2218514.9 | AH30: =+AE30 -> 52 | AI30: =+AG30 -> 2218514.9 | AJ30: =+AD30 -> 186 | AK30: =+AF30 -> 8171521.3 | AL30: 0 | AM30: 0 | AN30: 0 | AO30: 0 | AP30: 331.11328 | AQ30: Барқарор | AR30: =+AX30/$AX$28 -> 0.21276829 | AS30: 391470.67 | AT30: 97867.667 | AU30: Йуқ | AV30: Йуқ | AW30: 1 | AX30: =+AI30+AK30 -> 10390036
B31: 1130 | C31: Ипотека банк | D31: Ипотека банк Зангиота филиали | E31: 19 | F31: 6 | G31: 319698.75 | H31: 117586.61 | I31: 2 | J31: 42312 | K31: 16 | L31: 254198.75 | M31: 0 | N31: 0 | O31: 0 | P31: 0 | Q31: 3646.108 | R31: 54 | S31: =+VLOOKUP(B31,[1]Лист2!$A$4:$B$188,2,0) -> 11 | T31: 2834041.3 | U31: =+VLOOKUP(B31,[1]Лист2!$A$4:$C$188,3,0) -> 1492716.6 | V31: =+S31 -> 11 | W31: =+U31 -> 1492716.6 | X31: =+R31 -> 54 | Y31: =+T31 -> 2834041.3 | Z31: 0 | AA31: 0 | AB31: 0 | AC31: 0 | AD31: 45 | AE31: 11 | AF31: 1430822.5 | AG31: 766822.55 | AH31: =+AE31 -> 11 | AI31: =+AG31 -> 766822.55 | AJ31: =+AD31 -> 45 | AK31: =+AF31 -> 1430822.5 | AL31: 0 | AM31: 0 | AN31: 0 | AO31: 0 | AP31: 3707.5005 | AQ31: Ўртача | AR31: =+AX31/$AX$28 -> 0.045003615 | AS31: 27754.107 | AT31: 31256.059 | AU31: Бор | AV31: Бор | AW31: 2 | AX31: =+AI31+AK31 -> 2197645.1
B32: 11291 | C32: Туронбанк | D32: Туронбанк Зангиота филиали | E32: 127 | F32: 16 | G32: 3797021.6 | H32: 890187.23 | I32: 16 | J32: 890187.23 | K32: 127 | L32: 3797021.6 | M32: 0 | N32: 0 | O32: 0 | P32: 0 | Q32: 0 | R32: 172 | S32: =+VLOOKUP(B32,[1]Лист2!$A$4:$B$188,2,0) -> 47 | T32: 7047594.9 | U32: =+VLOOKUP(B32,[1]Лист2!$A$4:$C$188,3,0) -> 811033.88 | V32: =+S32 -> 47 | W32: =+U32 -> 811033.88 | X32: =+R32 -> 172 | Y32: =+T32 -> 7047594.9 | Z32: 0 | AA32: 0 | AB32: 0 | AC32: 0 | AD32: 148 | AE32: 80 | AF32: 9022267.1 | AG32: 5333256.8 | AH32: =+AE32 -> 80 | AI32: =+AG32 -> 5333256.8 | AJ32: =+AD32 -> 148 | AK32: =+AF32 -> 9022267.1 | AL32: 0 | AM32: 0 | AN32: 0 | AO32: 0 | AP32: 960.3055 | AQ32: Самарадор | AR32: =+AX32/$AX$28 -> 0.29397398 | AS32: 451129.33 | AT32: 112782.33 | AU32: Бор | AV32: Бор | AW32: 2 | AX32: =+AI32+AK32 -> 14355524
B33: 11853 | C33: Универсалбанк | D33: Универсалбанк Зангиота филиали | E33: 419 | F33: 13 | G33: 17106718 | H33: 240623.46 | I33: 10 | J33: 151629.78 | K33: 335 | L33: 15004506 | M33: 0 | N33: 0 | O33: 0 | P33: 0 | Q33: 279.16267 | R33: 393 | S33: =+VLOOKUP(B33,[1]Лист2!$A$4:$B$188,2,0) -> 10 | T33: 9483793 | U33: =+VLOOKUP(B33,[1]Лист2!$A$4:$C$188,3,0) -> 333552.99 | V33: =+S33 -> 10 | W33: =+U33 -> 333552.99 | X33: =+R33 -> 393 | Y33: =+T33 -> 9483793 | Z33: 0 | AA33: 0 | AB33: 0 | AC33: 0 | AD33: 679 | AE33: 2 | AF33: 12693159 | AG33: 11822.4 | AH33: =+AE33 -> 2 | AI33: =+AG33 -> 11822.4 | AJ33: =+AD33 -> 679 | AK33: =+AF33 -> 12693159 | AL33: 0 | AM33: 0 | AN33: 0 | AO33: 0 | AP33: 2498.8372 | AQ33: Самарадор | AR33: =+AX33/$AX$28 -> 0.26017399 | AS33: 262029.33 | AT33: 65507.333 | AU33: Бор | AV33: Йуқ | AW33: 1 | AX33: =+AI33+AK33 -> 12704981
B34: 11579 | C34: Халқ банк | D34: Халқ банк Зангиота БХМ | E34: 8 | F34: 7 | G34: 213179.18 | H34: 48096.16 | I34: 5 | J34: 34838.78 | K34: 3 | L34: 108800 | M34: 0 | N34: 0 | O34: 0 | P34: 0 | Q34: 1080.9696 | R34: 3 | T34: 149600 | V34: =+S34 -> 0 | W34: =+U34 -> 0 | X34: =+R34 -> 3 | Y34: =+T34 -> 149600 | Z34: =((+S34)/3)*4 -> 0 | AA34: =((+U34)/3)*4 -> 0 | AB34: 0 | AC34: 0 | AD34: 3 | AE34: 0 | AF34: 176401.5 | AG34: 0 | AH34: =+AE34 -> 0 | AI34: =+AG34 -> 0 | AJ34: =+AD34 -> 3 | AK34: =+AF34 -> 176401.5 | AL34: 0 | AM34: 0 | AN34: 0 | AO34: 0 | AP34: 224.64192 | AQ34: Самарадорлиги паст | AR34: =+AX34/$AX$28 -> 0.0036123691 | AS34: 0 | AT34: 0 | AU34: Бор | AV34: Бор | AW34: 2 | AX34: =+AI34+AK34 -> 176401.5
A35: Қибрай тумани | C35: Қибрай тумани | E35: =+SUM(E36:E38) -> 177 | F35: =+SUM(F36:F38) -> 205 | G35: =+SUM(G36:G38) -> 5871250.8 | H35: =+SUM(H36:H38) -> 19816751 | I35: =+SUM(I36:I38) -> 140 | J35: =+SUM(J36:J38) -> 14115374 | K35: =+SUM(K36:K38) -> 97 | L35: =+SUM(L36:L38) -> 2387557.6 | ... AP35: =+SUM(AP36:AP38) -> 13998.91 | AQ35: Ўртача | AR35: =+SUM(AR36:AR38) -> 1 | AS35: =+SUM(AS36:AS38) -> 255719.03 | AT35: =+SUM(AT36:AT38) -> 63929.757 | AW35: =+SUM(AW36:AW38) -> 5 | AX35: =+AI35+AK35+AM35+AO35 -> 16273776 | AY35: =+AX35/$AX$6 -> 0.025072552
B36: 1056 | C36: Инфинбанк | D36: Инфинбанк Қибрай филиали | E36: 159 | F36: 192 | G36: 5404388.5 | H36: 19227676 | I36: 129 | J36: 13736299 | K36: 87 | L36: 2059413 | M36: 0 | N36: 0 | O36: 0 | P36: 0 | Q36: 8315.4251 | R36: 96 | S36: =+VLOOKUP(B36,[1]Лист2!$A$4:$B$188,2,0) -> 138 | T36: 1333145.5 | U36: =+VLOOKUP(B36,[1]Лист2!$A$4:$C$188,3,0) -> 10797419 | V36: =+S36 -> 138 | W36: =+U36 -> 10797419 | X36: =+R36 -> 96 | Y36: =+T36 -> 1333145.5 | Z36: 0 | AA36: 0 | AB36: 0 | AC36: 0 | AD36: 104 | AE36: 179 | AF36: 2900235 | AG36: 12102516 | AH36: =+AE36 -> 179 | AI36: =+AG36 -> 12102516 | AJ36: =+AD36 -> 104 | AK36: =+AF36 -> 2900235 | AL36: 0 | AM36: 0 | AN36: 0 | AO36: 0 | AP36: 8356.3287 | AQ36: Самарадор | AR36: =+AX36/$AX$35 -> 0.92189731 | AS36: 235083.03 | AT36: 58770.757 | AU36: Йуқ | AV36: Бор | AW36: 1 | AX36: =+AI36+AK36 -> 15002751
B37: 11202 | C37: Ўзсаноатқурилишбанк | D37: Ўзсаноатқурилишбанк Қибрай БХМ | E37: 18 | F37: 13 | G37: 466862.28 | H37: 589075.01 | I37: 11 | J37: 379075.01 | K37: 10 | L37: 328144.68 | M37: 0 | N37: 0 | O37: 0 | P37: 0 | Q37: 809.20984 | R37: 11 | S37: =+VLOOKUP(B37,[1]Лист2!$A$4:$B$188,2,0) -> 10 | T37: 132868.46 | U37: =+VLOOKUP(B37,[1]Лист2!$A$4:$C$188,3,0) -> 100881.36 | V37: =+S37 -> 10 | W37: =+U37 -> 100881.36 | X37: =+R37 -> 11 | Y37: =+T37 -> 132868.46 | Z37: 0 | AA37: 0 | AB37: 0 | AC37: 0 | AD37: 27 | AE37: 10 | AF37: 534136.23 | AG37: 206826.62 | AH37: =+AE37 -> 10 | AI37: =+AG37 -> 206826.62 | AJ37: =+AD37 -> 27 | AK37: =+AF37 -> 534136.23 | AL37: 0 | AM37: 0 | AN37: 0 | AO37: 0 | AP37: 5409.6016 | AQ37: Самарадорлиги паст | AR37: =+AX37/$AX$35 -> 0.045531094 | AS37: 20636 | AT37: 5159 | AU37: Бор | AV37: Бор | AW37: 2 | AX37: =+AI37+AK37 -> 740962.85
B38: 11490 | C38: Халқ банк | D38: Халқ банк Қибрай БХМ | E38: 0 | F38: 0 | G38: 0 | H38: 0 | I38: 0 | J38: 0 | K38: 0 | L38: 0 | M38: 0 | N38: 0 | O38: 0 | P38: 0 | Q38: 941.60009 | R38: 11 | T38: 1050899.9 | V38: =+S38 -> 0 | W38: =+U38 -> 0 | X38: =+R38 -> 11 | Y38: =+T38 -> 1050899.9 | Z38: =((+S38)/3)*4 -> 0 | AA38: =((+U38)/3)*4 -> 0 | AB38: 0 | AC38: 0 | AD38: 6 | AE38: 0 | AF38: 530062.9 | AG38: 0 | AH38: =+AE38 -> 0 | AI38: =+AG38 -> 0 | AJ38: =+AD38 -> 6 | AK38: =+AF38 -> 530062.9 | AL38: 0 | AM38: 0 | AN38: 0 | AO38: 0 | AP38: 232.98013 | AQ38: Самарадорлиги паст | AR38: =+AX38/$AX$35 -> 0.032571598 | AS38: 0 | AT38: 0 | AU38: Бор | AV38: Бор | AW38: 2 | AX38: =+AI38+AK38 -> 530062.9
A39: Қуйичирчиқ тумани | C39: Қуйичирчиқ тумани | E39: =+E40 -> 1 | F39: =+F40 -> 0 | G39: =+G40 -> 14040 | H39: =+H40 -> 0 | I39: =+I40 -> 0 | J39: =+J40 -> 0 | K39: =+K40 -> 0 | L39: =+L40 -> 0 | ... AP39: =+AP40 -> 30.13978 | AQ39: Самарадорлиги паст | AS39: =+AS40 -> 0 | AT39: =+AT40 -> 0 | AW39: =+AW40 -> 2 | AX39: =+AI39+AK39+AM39+AO39 -> 0 | AY39: =+AX39/$AX$6 -> 0
B40: 474 | C40: Агробанк | D40: Агробанк Қуйичирчиқ филиали | E40: 1 | F40: 0 | G40: 14040 | H40: 0 | I40: 0 | J40: 0 | K40: 0 | L40: 0 | M40: 0 | N40: 0 | O40: 1 | P40: 14040 | Q40: 1.573 | R40: 1 | T40: 20000 | V40: =+S40 -> 0 | W40: =+U40 -> 0 | X40: =+R40 -> 1 | Y40: =+T40 -> 20000 | Z40: =((+S40)/3)*4 -> 0 | AA40: =((+U40)/3)*4 -> 0 | AB40: 0 | AC40: 0 | AD40: 0 | AE40: 0 | AF40: 0 | AG40: 0 | AH40: =+AE40 -> 0 | AI40: =+AG40 -> 0 | AJ40: =+AD40 -> 0 | AK40: =+AF40 -> 0 | AL40: 0 | AM40: 0 | AN40: 0 | AO40: 0 | AP40: 30.13978 | AQ40: Самарадорлиги паст | AS40: 0 | AT40: 0 | AU40: Бор | AV40: Бор | AW40: 2 | AX40: =+AI40+AK40 -> 0
...
